<?xml version="1.0"?>
<robot xmlns:xacro="http://www.ros.org/wiki/xacro">

  <xacro:macro name="mecanum_wheel" params="name x y z reflect_y">
    <link name="${name}">
      <visual>
        <geometry><cylinder length="0.04" radius="0.030"/></geometry>
        <origin xyz="0 0 0" rpy="${pi/2} 0 0"/>
        <material name="orange_wheel"><color rgba="0.95 0.55 0.1 1"/></material>
      </visual>
      <collision>
        <geometry><cylinder length="0.04" radius="0.030"/></geometry>
        <origin xyz="0 0 0" rpy="${pi/2} 0 0"/>
      </collision>
      <inertial>
        <mass value="0.300"/>
        <inertia ixx="0.000900" iyy="0.000900" izz="0.000135"
                 ixy="0" ixz="0" iyz="0"/>
      </inertial>
    </link>

    <joint name="${name}_joint" type="continuous">
      <parent link="base_link"/>
      <child  link="${name}"/>
      <origin xyz="${x} ${y} ${z}" rpy="0 0 0"/>
      <axis xyz="0 1 0"/>
      <dynamics damping="0.01" friction="0.1"/>
    </joint>
  </xacro:macro>

</robot>
